2019-12-26 23:20:34,686 - ERROR - Traceback (most recent call last):
  File "F:\python\duobaodao\Getgoods.py", line 221, in getUsedNo
    self.myqllink.commit()
  File "F:\python\duobaodao\lib\site-packages\pymysql\connections.py", line 420, in commit
    self._read_ok_packet()
  File "F:\python\duobaodao\lib\site-packages\pymysql\connections.py", line 394, in _read_ok_packet
    pkt = self._read_packet()
  File "F:\python\duobaodao\lib\site-packages\pymysql\connections.py", line 657, in _read_packet
    packet_header = self._read_bytes(4)
  File "F:\python\duobaodao\lib\site-packages\pymysql\connections.py", line 688, in _read_bytes
    self._sock.settimeout(self._read_timeout)
AttributeError: 'NoneType' object has no attribute 'settimeout'

