2020-02-19 20:51:34,193 - ERROR - Traceback (most recent call last):
  File "F:\python\duobaodao\Getgoods.py", line 240, in __setdata
    self.cursor.execute(sql)
  File "F:\python\duobaodao\lib\site-packages\pymysql\cursors.py", line 170, in execute
    result = self._query(query)
  File "F:\python\duobaodao\lib\site-packages\pymysql\cursors.py", line 328, in _query
    conn.query(q)
  File "F:\python\duobaodao\lib\site-packages\pymysql\connections.py", line 517, in query
    self._affected_rows = self._read_query_result(unbuffered=unbuffered)
  File "F:\python\duobaodao\lib\site-packages\pymysql\connections.py", line 732, in _read_query_result
    result.read()
  File "F:\python\duobaodao\lib\site-packages\pymysql\connections.py", line 1075, in read
    first_packet = self.connection._read_packet()
  File "F:\python\duobaodao\lib\site-packages\pymysql\connections.py", line 684, in _read_packet
    packet.check_error()
  File "F:\python\duobaodao\lib\site-packages\pymysql\protocol.py", line 220, in check_error
    err.raise_mysql_exception(self._data)
  File "F:\python\duobaodao\lib\site-packages\pymysql\err.py", line 109, in raise_mysql_exception
    raise errorclass(errno, errval)
pymysql.err.IntegrityError: (1062, "Duplicate entry '202993734' for key 'goodsid'")

2020-02-19 20:51:34,462 - ERROR - Traceback (most recent call last):
  File "F:\python\duobaodao\Getgoods.py", line 240, in __setdata
    self.cursor.execute(sql)
  File "F:\python\duobaodao\lib\site-packages\pymysql\cursors.py", line 170, in execute
    result = self._query(query)
  File "F:\python\duobaodao\lib\site-packages\pymysql\cursors.py", line 328, in _query
    conn.query(q)
  File "F:\python\duobaodao\lib\site-packages\pymysql\connections.py", line 517, in query
    self._affected_rows = self._read_query_result(unbuffered=unbuffered)
  File "F:\python\duobaodao\lib\site-packages\pymysql\connections.py", line 732, in _read_query_result
    result.read()
  File "F:\python\duobaodao\lib\site-packages\pymysql\connections.py", line 1075, in read
    first_packet = self.connection._read_packet()
  File "F:\python\duobaodao\lib\site-packages\pymysql\connections.py", line 684, in _read_packet
    packet.check_error()
  File "F:\python\duobaodao\lib\site-packages\pymysql\protocol.py", line 220, in check_error
    err.raise_mysql_exception(self._data)
  File "F:\python\duobaodao\lib\site-packages\pymysql\err.py", line 109, in raise_mysql_exception
    raise errorclass(errno, errval)
pymysql.err.IntegrityError: (1062, "Duplicate entry '202994434' for key 'goodsid'")

2020-02-19 20:51:36,132 - ERROR - Traceback (most recent call last):
  File "F:\python\duobaodao\Getgoods.py", line 240, in __setdata
    self.cursor.execute(sql)
  File "F:\python\duobaodao\lib\site-packages\pymysql\cursors.py", line 170, in execute
    result = self._query(query)
  File "F:\python\duobaodao\lib\site-packages\pymysql\cursors.py", line 328, in _query
    conn.query(q)
  File "F:\python\duobaodao\lib\site-packages\pymysql\connections.py", line 517, in query
    self._affected_rows = self._read_query_result(unbuffered=unbuffered)
  File "F:\python\duobaodao\lib\site-packages\pymysql\connections.py", line 732, in _read_query_result
    result.read()
  File "F:\python\duobaodao\lib\site-packages\pymysql\connections.py", line 1075, in read
    first_packet = self.connection._read_packet()
  File "F:\python\duobaodao\lib\site-packages\pymysql\connections.py", line 684, in _read_packet
    packet.check_error()
  File "F:\python\duobaodao\lib\site-packages\pymysql\protocol.py", line 220, in check_error
    err.raise_mysql_exception(self._data)
  File "F:\python\duobaodao\lib\site-packages\pymysql\err.py", line 109, in raise_mysql_exception
    raise errorclass(errno, errval)
pymysql.err.IntegrityError: (1062, "Duplicate entry '203059660' for key 'goodsid'")

2020-02-19 20:51:36,391 - ERROR - Traceback (most recent call last):
  File "F:\python\duobaodao\Getgoods.py", line 240, in __setdata
    self.cursor.execute(sql)
  File "F:\python\duobaodao\lib\site-packages\pymysql\cursors.py", line 170, in execute
    result = self._query(query)
  File "F:\python\duobaodao\lib\site-packages\pymysql\cursors.py", line 328, in _query
    conn.query(q)
  File "F:\python\duobaodao\lib\site-packages\pymysql\connections.py", line 517, in query
    self._affected_rows = self._read_query_result(unbuffered=unbuffered)
  File "F:\python\duobaodao\lib\site-packages\pymysql\connections.py", line 732, in _read_query_result
    result.read()
  File "F:\python\duobaodao\lib\site-packages\pymysql\connections.py", line 1075, in read
    first_packet = self.connection._read_packet()
  File "F:\python\duobaodao\lib\site-packages\pymysql\connections.py", line 684, in _read_packet
    packet.check_error()
  File "F:\python\duobaodao\lib\site-packages\pymysql\protocol.py", line 220, in check_error
    err.raise_mysql_exception(self._data)
  File "F:\python\duobaodao\lib\site-packages\pymysql\err.py", line 109, in raise_mysql_exception
    raise errorclass(errno, errval)
pymysql.err.IntegrityError: (1062, "Duplicate entry '203060210' for key 'goodsid'")

2020-02-19 20:51:36,661 - ERROR - Traceback (most recent call last):
  File "F:\python\duobaodao\Getgoods.py", line 240, in __setdata
    self.cursor.execute(sql)
  File "F:\python\duobaodao\lib\site-packages\pymysql\cursors.py", line 170, in execute
    result = self._query(query)
  File "F:\python\duobaodao\lib\site-packages\pymysql\cursors.py", line 328, in _query
    conn.query(q)
  File "F:\python\duobaodao\lib\site-packages\pymysql\connections.py", line 517, in query
    self._affected_rows = self._read_query_result(unbuffered=unbuffered)
  File "F:\python\duobaodao\lib\site-packages\pymysql\connections.py", line 732, in _read_query_result
    result.read()
  File "F:\python\duobaodao\lib\site-packages\pymysql\connections.py", line 1075, in read
    first_packet = self.connection._read_packet()
  File "F:\python\duobaodao\lib\site-packages\pymysql\connections.py", line 684, in _read_packet
    packet.check_error()
  File "F:\python\duobaodao\lib\site-packages\pymysql\protocol.py", line 220, in check_error
    err.raise_mysql_exception(self._data)
  File "F:\python\duobaodao\lib\site-packages\pymysql\err.py", line 109, in raise_mysql_exception
    raise errorclass(errno, errval)
pymysql.err.IntegrityError: (1062, "Duplicate entry '203035833' for key 'goodsid'")

2020-02-19 20:51:36,923 - ERROR - Traceback (most recent call last):
  File "F:\python\duobaodao\Getgoods.py", line 240, in __setdata
    self.cursor.execute(sql)
  File "F:\python\duobaodao\lib\site-packages\pymysql\cursors.py", line 170, in execute
    result = self._query(query)
  File "F:\python\duobaodao\lib\site-packages\pymysql\cursors.py", line 328, in _query
    conn.query(q)
  File "F:\python\duobaodao\lib\site-packages\pymysql\connections.py", line 517, in query
    self._affected_rows = self._read_query_result(unbuffered=unbuffered)
  File "F:\python\duobaodao\lib\site-packages\pymysql\connections.py", line 732, in _read_query_result
    result.read()
  File "F:\python\duobaodao\lib\site-packages\pymysql\connections.py", line 1075, in read
    first_packet = self.connection._read_packet()
  File "F:\python\duobaodao\lib\site-packages\pymysql\connections.py", line 684, in _read_packet
    packet.check_error()
  File "F:\python\duobaodao\lib\site-packages\pymysql\protocol.py", line 220, in check_error
    err.raise_mysql_exception(self._data)
  File "F:\python\duobaodao\lib\site-packages\pymysql\err.py", line 109, in raise_mysql_exception
    raise errorclass(errno, errval)
pymysql.err.IntegrityError: (1062, "Duplicate entry '203059604' for key 'goodsid'")

2020-02-19 20:51:37,184 - ERROR - Traceback (most recent call last):
  File "F:\python\duobaodao\Getgoods.py", line 240, in __setdata
    self.cursor.execute(sql)
  File "F:\python\duobaodao\lib\site-packages\pymysql\cursors.py", line 170, in execute
    result = self._query(query)
  File "F:\python\duobaodao\lib\site-packages\pymysql\cursors.py", line 328, in _query
    conn.query(q)
  File "F:\python\duobaodao\lib\site-packages\pymysql\connections.py", line 517, in query
    self._affected_rows = self._read_query_result(unbuffered=unbuffered)
  File "F:\python\duobaodao\lib\site-packages\pymysql\connections.py", line 732, in _read_query_result
    result.read()
  File "F:\python\duobaodao\lib\site-packages\pymysql\connections.py", line 1075, in read
    first_packet = self.connection._read_packet()
  File "F:\python\duobaodao\lib\site-packages\pymysql\connections.py", line 684, in _read_packet
    packet.check_error()
  File "F:\python\duobaodao\lib\site-packages\pymysql\protocol.py", line 220, in check_error
    err.raise_mysql_exception(self._data)
  File "F:\python\duobaodao\lib\site-packages\pymysql\err.py", line 109, in raise_mysql_exception
    raise errorclass(errno, errval)
pymysql.err.IntegrityError: (1062, "Duplicate entry '202994168' for key 'goodsid'")

2020-02-19 20:51:37,565 - ERROR - Traceback (most recent call last):
  File "F:\python\duobaodao\Getgoods.py", line 240, in __setdata
    self.cursor.execute(sql)
  File "F:\python\duobaodao\lib\site-packages\pymysql\cursors.py", line 170, in execute
    result = self._query(query)
  File "F:\python\duobaodao\lib\site-packages\pymysql\cursors.py", line 328, in _query
    conn.query(q)
  File "F:\python\duobaodao\lib\site-packages\pymysql\connections.py", line 517, in query
    self._affected_rows = self._read_query_result(unbuffered=unbuffered)
  File "F:\python\duobaodao\lib\site-packages\pymysql\connections.py", line 732, in _read_query_result
    result.read()
  File "F:\python\duobaodao\lib\site-packages\pymysql\connections.py", line 1075, in read
    first_packet = self.connection._read_packet()
  File "F:\python\duobaodao\lib\site-packages\pymysql\connections.py", line 684, in _read_packet
    packet.check_error()
  File "F:\python\duobaodao\lib\site-packages\pymysql\protocol.py", line 220, in check_error
    err.raise_mysql_exception(self._data)
  File "F:\python\duobaodao\lib\site-packages\pymysql\err.py", line 109, in raise_mysql_exception
    raise errorclass(errno, errval)
pymysql.err.IntegrityError: (1062, "Duplicate entry '203015803' for key 'goodsid'")

2020-02-19 20:51:37,947 - ERROR - Traceback (most recent call last):
  File "F:\python\duobaodao\Getgoods.py", line 240, in __setdata
    self.cursor.execute(sql)
  File "F:\python\duobaodao\lib\site-packages\pymysql\cursors.py", line 170, in execute
    result = self._query(query)
  File "F:\python\duobaodao\lib\site-packages\pymysql\cursors.py", line 328, in _query
    conn.query(q)
  File "F:\python\duobaodao\lib\site-packages\pymysql\connections.py", line 517, in query
    self._affected_rows = self._read_query_result(unbuffered=unbuffered)
  File "F:\python\duobaodao\lib\site-packages\pymysql\connections.py", line 732, in _read_query_result
    result.read()
  File "F:\python\duobaodao\lib\site-packages\pymysql\connections.py", line 1075, in read
    first_packet = self.connection._read_packet()
  File "F:\python\duobaodao\lib\site-packages\pymysql\connections.py", line 684, in _read_packet
    packet.check_error()
  File "F:\python\duobaodao\lib\site-packages\pymysql\protocol.py", line 220, in check_error
    err.raise_mysql_exception(self._data)
  File "F:\python\duobaodao\lib\site-packages\pymysql\err.py", line 109, in raise_mysql_exception
    raise errorclass(errno, errval)
pymysql.err.IntegrityError: (1062, "Duplicate entry '203070820' for key 'goodsid'")

2020-02-19 20:51:38,219 - ERROR - Traceback (most recent call last):
  File "F:\python\duobaodao\Getgoods.py", line 240, in __setdata
    self.cursor.execute(sql)
  File "F:\python\duobaodao\lib\site-packages\pymysql\cursors.py", line 170, in execute
    result = self._query(query)
  File "F:\python\duobaodao\lib\site-packages\pymysql\cursors.py", line 328, in _query
    conn.query(q)
  File "F:\python\duobaodao\lib\site-packages\pymysql\connections.py", line 517, in query
    self._affected_rows = self._read_query_result(unbuffered=unbuffered)
  File "F:\python\duobaodao\lib\site-packages\pymysql\connections.py", line 732, in _read_query_result
    result.read()
  File "F:\python\duobaodao\lib\site-packages\pymysql\connections.py", line 1075, in read
    first_packet = self.connection._read_packet()
  File "F:\python\duobaodao\lib\site-packages\pymysql\connections.py", line 684, in _read_packet
    packet.check_error()
  File "F:\python\duobaodao\lib\site-packages\pymysql\protocol.py", line 220, in check_error
    err.raise_mysql_exception(self._data)
  File "F:\python\duobaodao\lib\site-packages\pymysql\err.py", line 109, in raise_mysql_exception
    raise errorclass(errno, errval)
pymysql.err.IntegrityError: (1062, "Duplicate entry '203036263' for key 'goodsid'")

2020-02-19 20:51:38,482 - ERROR - Traceback (most recent call last):
  File "F:\python\duobaodao\Getgoods.py", line 240, in __setdata
    self.cursor.execute(sql)
  File "F:\python\duobaodao\lib\site-packages\pymysql\cursors.py", line 170, in execute
    result = self._query(query)
  File "F:\python\duobaodao\lib\site-packages\pymysql\cursors.py", line 328, in _query
    conn.query(q)
  File "F:\python\duobaodao\lib\site-packages\pymysql\connections.py", line 517, in query
    self._affected_rows = self._read_query_result(unbuffered=unbuffered)
  File "F:\python\duobaodao\lib\site-packages\pymysql\connections.py", line 732, in _read_query_result
    result.read()
  File "F:\python\duobaodao\lib\site-packages\pymysql\connections.py", line 1075, in read
    first_packet = self.connection._read_packet()
  File "F:\python\duobaodao\lib\site-packages\pymysql\connections.py", line 684, in _read_packet
    packet.check_error()
  File "F:\python\duobaodao\lib\site-packages\pymysql\protocol.py", line 220, in check_error
    err.raise_mysql_exception(self._data)
  File "F:\python\duobaodao\lib\site-packages\pymysql\err.py", line 109, in raise_mysql_exception
    raise errorclass(errno, errval)
pymysql.err.IntegrityError: (1062, "Duplicate entry '203070823' for key 'goodsid'")

2020-02-19 20:51:38,747 - ERROR - Traceback (most recent call last):
  File "F:\python\duobaodao\Getgoods.py", line 240, in __setdata
    self.cursor.execute(sql)
  File "F:\python\duobaodao\lib\site-packages\pymysql\cursors.py", line 170, in execute
    result = self._query(query)
  File "F:\python\duobaodao\lib\site-packages\pymysql\cursors.py", line 328, in _query
    conn.query(q)
  File "F:\python\duobaodao\lib\site-packages\pymysql\connections.py", line 517, in query
    self._affected_rows = self._read_query_result(unbuffered=unbuffered)
  File "F:\python\duobaodao\lib\site-packages\pymysql\connections.py", line 732, in _read_query_result
    result.read()
  File "F:\python\duobaodao\lib\site-packages\pymysql\connections.py", line 1075, in read
    first_packet = self.connection._read_packet()
  File "F:\python\duobaodao\lib\site-packages\pymysql\connections.py", line 684, in _read_packet
    packet.check_error()
  File "F:\python\duobaodao\lib\site-packages\pymysql\protocol.py", line 220, in check_error
    err.raise_mysql_exception(self._data)
  File "F:\python\duobaodao\lib\site-packages\pymysql\err.py", line 109, in raise_mysql_exception
    raise errorclass(errno, errval)
pymysql.err.IntegrityError: (1062, "Duplicate entry '203058911' for key 'goodsid'")

2020-02-19 20:51:39,130 - ERROR - Traceback (most recent call last):
  File "F:\python\duobaodao\Getgoods.py", line 240, in __setdata
    self.cursor.execute(sql)
  File "F:\python\duobaodao\lib\site-packages\pymysql\cursors.py", line 170, in execute
    result = self._query(query)
  File "F:\python\duobaodao\lib\site-packages\pymysql\cursors.py", line 328, in _query
    conn.query(q)
  File "F:\python\duobaodao\lib\site-packages\pymysql\connections.py", line 517, in query
    self._affected_rows = self._read_query_result(unbuffered=unbuffered)
  File "F:\python\duobaodao\lib\site-packages\pymysql\connections.py", line 732, in _read_query_result
    result.read()
  File "F:\python\duobaodao\lib\site-packages\pymysql\connections.py", line 1075, in read
    first_packet = self.connection._read_packet()
  File "F:\python\duobaodao\lib\site-packages\pymysql\connections.py", line 684, in _read_packet
    packet.check_error()
  File "F:\python\duobaodao\lib\site-packages\pymysql\protocol.py", line 220, in check_error
    err.raise_mysql_exception(self._data)
  File "F:\python\duobaodao\lib\site-packages\pymysql\err.py", line 109, in raise_mysql_exception
    raise errorclass(errno, errval)
pymysql.err.IntegrityError: (1062, "Duplicate entry '203001683' for key 'goodsid'")

2020-02-19 20:51:39,401 - ERROR - Traceback (most recent call last):
  File "F:\python\duobaodao\Getgoods.py", line 240, in __setdata
    self.cursor.execute(sql)
  File "F:\python\duobaodao\lib\site-packages\pymysql\cursors.py", line 170, in execute
    result = self._query(query)
  File "F:\python\duobaodao\lib\site-packages\pymysql\cursors.py", line 328, in _query
    conn.query(q)
  File "F:\python\duobaodao\lib\site-packages\pymysql\connections.py", line 517, in query
    self._affected_rows = self._read_query_result(unbuffered=unbuffered)
  File "F:\python\duobaodao\lib\site-packages\pymysql\connections.py", line 732, in _read_query_result
    result.read()
  File "F:\python\duobaodao\lib\site-packages\pymysql\connections.py", line 1075, in read
    first_packet = self.connection._read_packet()
  File "F:\python\duobaodao\lib\site-packages\pymysql\connections.py", line 684, in _read_packet
    packet.check_error()
  File "F:\python\duobaodao\lib\site-packages\pymysql\protocol.py", line 220, in check_error
    err.raise_mysql_exception(self._data)
  File "F:\python\duobaodao\lib\site-packages\pymysql\err.py", line 109, in raise_mysql_exception
    raise errorclass(errno, errval)
pymysql.err.IntegrityError: (1062, "Duplicate entry '202986525' for key 'goodsid'")

2020-02-19 20:51:39,662 - ERROR - Traceback (most recent call last):
  File "F:\python\duobaodao\Getgoods.py", line 240, in __setdata
    self.cursor.execute(sql)
  File "F:\python\duobaodao\lib\site-packages\pymysql\cursors.py", line 170, in execute
    result = self._query(query)
  File "F:\python\duobaodao\lib\site-packages\pymysql\cursors.py", line 328, in _query
    conn.query(q)
  File "F:\python\duobaodao\lib\site-packages\pymysql\connections.py", line 517, in query
    self._affected_rows = self._read_query_result(unbuffered=unbuffered)
  File "F:\python\duobaodao\lib\site-packages\pymysql\connections.py", line 732, in _read_query_result
    result.read()
  File "F:\python\duobaodao\lib\site-packages\pymysql\connections.py", line 1075, in read
    first_packet = self.connection._read_packet()
  File "F:\python\duobaodao\lib\site-packages\pymysql\connections.py", line 684, in _read_packet
    packet.check_error()
  File "F:\python\duobaodao\lib\site-packages\pymysql\protocol.py", line 220, in check_error
    err.raise_mysql_exception(self._data)
  File "F:\python\duobaodao\lib\site-packages\pymysql\err.py", line 109, in raise_mysql_exception
    raise errorclass(errno, errval)
pymysql.err.IntegrityError: (1062, "Duplicate entry '203070828' for key 'goodsid'")

2020-02-19 20:51:40,051 - ERROR - Traceback (most recent call last):
  File "F:\python\duobaodao\Getgoods.py", line 240, in __setdata
    self.cursor.execute(sql)
  File "F:\python\duobaodao\lib\site-packages\pymysql\cursors.py", line 170, in execute
    result = self._query(query)
  File "F:\python\duobaodao\lib\site-packages\pymysql\cursors.py", line 328, in _query
    conn.query(q)
  File "F:\python\duobaodao\lib\site-packages\pymysql\connections.py", line 517, in query
    self._affected_rows = self._read_query_result(unbuffered=unbuffered)
  File "F:\python\duobaodao\lib\site-packages\pymysql\connections.py", line 732, in _read_query_result
    result.read()
  File "F:\python\duobaodao\lib\site-packages\pymysql\connections.py", line 1075, in read
    first_packet = self.connection._read_packet()
  File "F:\python\duobaodao\lib\site-packages\pymysql\connections.py", line 684, in _read_packet
    packet.check_error()
  File "F:\python\duobaodao\lib\site-packages\pymysql\protocol.py", line 220, in check_error
    err.raise_mysql_exception(self._data)
  File "F:\python\duobaodao\lib\site-packages\pymysql\err.py", line 109, in raise_mysql_exception
    raise errorclass(errno, errval)
pymysql.err.IntegrityError: (1062, "Duplicate entry '203004668' for key 'goodsid'")

2020-02-19 20:51:40,360 - ERROR - Traceback (most recent call last):
  File "F:\python\duobaodao\Getgoods.py", line 240, in __setdata
    self.cursor.execute(sql)
  File "F:\python\duobaodao\lib\site-packages\pymysql\cursors.py", line 170, in execute
    result = self._query(query)
  File "F:\python\duobaodao\lib\site-packages\pymysql\cursors.py", line 328, in _query
    conn.query(q)
  File "F:\python\duobaodao\lib\site-packages\pymysql\connections.py", line 517, in query
    self._affected_rows = self._read_query_result(unbuffered=unbuffered)
  File "F:\python\duobaodao\lib\site-packages\pymysql\connections.py", line 732, in _read_query_result
    result.read()
  File "F:\python\duobaodao\lib\site-packages\pymysql\connections.py", line 1075, in read
    first_packet = self.connection._read_packet()
  File "F:\python\duobaodao\lib\site-packages\pymysql\connections.py", line 684, in _read_packet
    packet.check_error()
  File "F:\python\duobaodao\lib\site-packages\pymysql\protocol.py", line 220, in check_error
    err.raise_mysql_exception(self._data)
  File "F:\python\duobaodao\lib\site-packages\pymysql\err.py", line 109, in raise_mysql_exception
    raise errorclass(errno, errval)
pymysql.err.IntegrityError: (1062, "Duplicate entry '202993735' for key 'goodsid'")

2020-02-19 20:51:40,741 - ERROR - Traceback (most recent call last):
  File "F:\python\duobaodao\Getgoods.py", line 240, in __setdata
    self.cursor.execute(sql)
  File "F:\python\duobaodao\lib\site-packages\pymysql\cursors.py", line 170, in execute
    result = self._query(query)
  File "F:\python\duobaodao\lib\site-packages\pymysql\cursors.py", line 328, in _query
    conn.query(q)
  File "F:\python\duobaodao\lib\site-packages\pymysql\connections.py", line 517, in query
    self._affected_rows = self._read_query_result(unbuffered=unbuffered)
  File "F:\python\duobaodao\lib\site-packages\pymysql\connections.py", line 732, in _read_query_result
    result.read()
  File "F:\python\duobaodao\lib\site-packages\pymysql\connections.py", line 1075, in read
    first_packet = self.connection._read_packet()
  File "F:\python\duobaodao\lib\site-packages\pymysql\connections.py", line 684, in _read_packet
    packet.check_error()
  File "F:\python\duobaodao\lib\site-packages\pymysql\protocol.py", line 220, in check_error
    err.raise_mysql_exception(self._data)
  File "F:\python\duobaodao\lib\site-packages\pymysql\err.py", line 109, in raise_mysql_exception
    raise errorclass(errno, errval)
pymysql.err.IntegrityError: (1062, "Duplicate entry '203033293' for key 'goodsid'")

2020-02-19 20:51:40,999 - ERROR - Traceback (most recent call last):
  File "F:\python\duobaodao\Getgoods.py", line 240, in __setdata
    self.cursor.execute(sql)
  File "F:\python\duobaodao\lib\site-packages\pymysql\cursors.py", line 170, in execute
    result = self._query(query)
  File "F:\python\duobaodao\lib\site-packages\pymysql\cursors.py", line 328, in _query
    conn.query(q)
  File "F:\python\duobaodao\lib\site-packages\pymysql\connections.py", line 517, in query
    self._affected_rows = self._read_query_result(unbuffered=unbuffered)
  File "F:\python\duobaodao\lib\site-packages\pymysql\connections.py", line 732, in _read_query_result
    result.read()
  File "F:\python\duobaodao\lib\site-packages\pymysql\connections.py", line 1075, in read
    first_packet = self.connection._read_packet()
  File "F:\python\duobaodao\lib\site-packages\pymysql\connections.py", line 684, in _read_packet
    packet.check_error()
  File "F:\python\duobaodao\lib\site-packages\pymysql\protocol.py", line 220, in check_error
    err.raise_mysql_exception(self._data)
  File "F:\python\duobaodao\lib\site-packages\pymysql\err.py", line 109, in raise_mysql_exception
    raise errorclass(errno, errval)
pymysql.err.IntegrityError: (1062, "Duplicate entry '202994435' for key 'goodsid'")

2020-02-19 20:51:41,375 - ERROR - Traceback (most recent call last):
  File "F:\python\duobaodao\Getgoods.py", line 240, in __setdata
    self.cursor.execute(sql)
  File "F:\python\duobaodao\lib\site-packages\pymysql\cursors.py", line 170, in execute
    result = self._query(query)
  File "F:\python\duobaodao\lib\site-packages\pymysql\cursors.py", line 328, in _query
    conn.query(q)
  File "F:\python\duobaodao\lib\site-packages\pymysql\connections.py", line 517, in query
    self._affected_rows = self._read_query_result(unbuffered=unbuffered)
  File "F:\python\duobaodao\lib\site-packages\pymysql\connections.py", line 732, in _read_query_result
    result.read()
  File "F:\python\duobaodao\lib\site-packages\pymysql\connections.py", line 1075, in read
    first_packet = self.connection._read_packet()
  File "F:\python\duobaodao\lib\site-packages\pymysql\connections.py", line 684, in _read_packet
    packet.check_error()
  File "F:\python\duobaodao\lib\site-packages\pymysql\protocol.py", line 220, in check_error
    err.raise_mysql_exception(self._data)
  File "F:\python\duobaodao\lib\site-packages\pymysql\err.py", line 109, in raise_mysql_exception
    raise errorclass(errno, errval)
pymysql.err.IntegrityError: (1062, "Duplicate entry '202994169' for key 'goodsid'")

2020-02-19 20:51:41,759 - ERROR - Traceback (most recent call last):
  File "F:\python\duobaodao\Getgoods.py", line 240, in __setdata
    self.cursor.execute(sql)
  File "F:\python\duobaodao\lib\site-packages\pymysql\cursors.py", line 170, in execute
    result = self._query(query)
  File "F:\python\duobaodao\lib\site-packages\pymysql\cursors.py", line 328, in _query
    conn.query(q)
  File "F:\python\duobaodao\lib\site-packages\pymysql\connections.py", line 517, in query
    self._affected_rows = self._read_query_result(unbuffered=unbuffered)
  File "F:\python\duobaodao\lib\site-packages\pymysql\connections.py", line 732, in _read_query_result
    result.read()
  File "F:\python\duobaodao\lib\site-packages\pymysql\connections.py", line 1075, in read
    first_packet = self.connection._read_packet()
  File "F:\python\duobaodao\lib\site-packages\pymysql\connections.py", line 684, in _read_packet
    packet.check_error()
  File "F:\python\duobaodao\lib\site-packages\pymysql\protocol.py", line 220, in check_error
    err.raise_mysql_exception(self._data)
  File "F:\python\duobaodao\lib\site-packages\pymysql\err.py", line 109, in raise_mysql_exception
    raise errorclass(errno, errval)
pymysql.err.IntegrityError: (1062, "Duplicate entry '203058705' for key 'goodsid'")

2020-02-19 20:51:42,130 - ERROR - Traceback (most recent call last):
  File "F:\python\duobaodao\Getgoods.py", line 240, in __setdata
    self.cursor.execute(sql)
  File "F:\python\duobaodao\lib\site-packages\pymysql\cursors.py", line 170, in execute
    result = self._query(query)
  File "F:\python\duobaodao\lib\site-packages\pymysql\cursors.py", line 328, in _query
    conn.query(q)
  File "F:\python\duobaodao\lib\site-packages\pymysql\connections.py", line 517, in query
    self._affected_rows = self._read_query_result(unbuffered=unbuffered)
  File "F:\python\duobaodao\lib\site-packages\pymysql\connections.py", line 732, in _read_query_result
    result.read()
  File "F:\python\duobaodao\lib\site-packages\pymysql\connections.py", line 1075, in read
    first_packet = self.connection._read_packet()
  File "F:\python\duobaodao\lib\site-packages\pymysql\connections.py", line 684, in _read_packet
    packet.check_error()
  File "F:\python\duobaodao\lib\site-packages\pymysql\protocol.py", line 220, in check_error
    err.raise_mysql_exception(self._data)
  File "F:\python\duobaodao\lib\site-packages\pymysql\err.py", line 109, in raise_mysql_exception
    raise errorclass(errno, errval)
pymysql.err.IntegrityError: (1062, "Duplicate entry '203070838' for key 'goodsid'")

2020-02-19 20:51:42,395 - ERROR - Traceback (most recent call last):
  File "F:\python\duobaodao\Getgoods.py", line 240, in __setdata
    self.cursor.execute(sql)
  File "F:\python\duobaodao\lib\site-packages\pymysql\cursors.py", line 170, in execute
    result = self._query(query)
  File "F:\python\duobaodao\lib\site-packages\pymysql\cursors.py", line 328, in _query
    conn.query(q)
  File "F:\python\duobaodao\lib\site-packages\pymysql\connections.py", line 517, in query
    self._affected_rows = self._read_query_result(unbuffered=unbuffered)
  File "F:\python\duobaodao\lib\site-packages\pymysql\connections.py", line 732, in _read_query_result
    result.read()
  File "F:\python\duobaodao\lib\site-packages\pymysql\connections.py", line 1075, in read
    first_packet = self.connection._read_packet()
  File "F:\python\duobaodao\lib\site-packages\pymysql\connections.py", line 684, in _read_packet
    packet.check_error()
  File "F:\python\duobaodao\lib\site-packages\pymysql\protocol.py", line 220, in check_error
    err.raise_mysql_exception(self._data)
  File "F:\python\duobaodao\lib\site-packages\pymysql\err.py", line 109, in raise_mysql_exception
    raise errorclass(errno, errval)
pymysql.err.IntegrityError: (1062, "Duplicate entry '203058675' for key 'goodsid'")

2020-02-19 20:51:42,657 - ERROR - Traceback (most recent call last):
  File "F:\python\duobaodao\Getgoods.py", line 240, in __setdata
    self.cursor.execute(sql)
  File "F:\python\duobaodao\lib\site-packages\pymysql\cursors.py", line 170, in execute
    result = self._query(query)
  File "F:\python\duobaodao\lib\site-packages\pymysql\cursors.py", line 328, in _query
    conn.query(q)
  File "F:\python\duobaodao\lib\site-packages\pymysql\connections.py", line 517, in query
    self._affected_rows = self._read_query_result(unbuffered=unbuffered)
  File "F:\python\duobaodao\lib\site-packages\pymysql\connections.py", line 732, in _read_query_result
    result.read()
  File "F:\python\duobaodao\lib\site-packages\pymysql\connections.py", line 1075, in read
    first_packet = self.connection._read_packet()
  File "F:\python\duobaodao\lib\site-packages\pymysql\connections.py", line 684, in _read_packet
    packet.check_error()
  File "F:\python\duobaodao\lib\site-packages\pymysql\protocol.py", line 220, in check_error
    err.raise_mysql_exception(self._data)
  File "F:\python\duobaodao\lib\site-packages\pymysql\err.py", line 109, in raise_mysql_exception
    raise errorclass(errno, errval)
pymysql.err.IntegrityError: (1062, "Duplicate entry '203058543' for key 'goodsid'")

2020-02-19 20:51:43,028 - ERROR - Traceback (most recent call last):
  File "F:\python\duobaodao\Getgoods.py", line 240, in __setdata
    self.cursor.execute(sql)
  File "F:\python\duobaodao\lib\site-packages\pymysql\cursors.py", line 170, in execute
    result = self._query(query)
  File "F:\python\duobaodao\lib\site-packages\pymysql\cursors.py", line 328, in _query
    conn.query(q)
  File "F:\python\duobaodao\lib\site-packages\pymysql\connections.py", line 517, in query
    self._affected_rows = self._read_query_result(unbuffered=unbuffered)
  File "F:\python\duobaodao\lib\site-packages\pymysql\connections.py", line 732, in _read_query_result
    result.read()
  File "F:\python\duobaodao\lib\site-packages\pymysql\connections.py", line 1075, in read
    first_packet = self.connection._read_packet()
  File "F:\python\duobaodao\lib\site-packages\pymysql\connections.py", line 684, in _read_packet
    packet.check_error()
  File "F:\python\duobaodao\lib\site-packages\pymysql\protocol.py", line 220, in check_error
    err.raise_mysql_exception(self._data)
  File "F:\python\duobaodao\lib\site-packages\pymysql\err.py", line 109, in raise_mysql_exception
    raise errorclass(errno, errval)
pymysql.err.IntegrityError: (1062, "Duplicate entry '202986933' for key 'goodsid'")

2020-02-19 20:51:43,411 - ERROR - Traceback (most recent call last):
  File "F:\python\duobaodao\Getgoods.py", line 240, in __setdata
    self.cursor.execute(sql)
  File "F:\python\duobaodao\lib\site-packages\pymysql\cursors.py", line 170, in execute
    result = self._query(query)
  File "F:\python\duobaodao\lib\site-packages\pymysql\cursors.py", line 328, in _query
    conn.query(q)
  File "F:\python\duobaodao\lib\site-packages\pymysql\connections.py", line 517, in query
    self._affected_rows = self._read_query_result(unbuffered=unbuffered)
  File "F:\python\duobaodao\lib\site-packages\pymysql\connections.py", line 732, in _read_query_result
    result.read()
  File "F:\python\duobaodao\lib\site-packages\pymysql\connections.py", line 1075, in read
    first_packet = self.connection._read_packet()
  File "F:\python\duobaodao\lib\site-packages\pymysql\connections.py", line 684, in _read_packet
    packet.check_error()
  File "F:\python\duobaodao\lib\site-packages\pymysql\protocol.py", line 220, in check_error
    err.raise_mysql_exception(self._data)
  File "F:\python\duobaodao\lib\site-packages\pymysql\err.py", line 109, in raise_mysql_exception
    raise errorclass(errno, errval)
pymysql.err.IntegrityError: (1062, "Duplicate entry '203070840' for key 'goodsid'")

2020-02-19 20:51:43,686 - ERROR - Traceback (most recent call last):
  File "F:\python\duobaodao\Getgoods.py", line 240, in __setdata
    self.cursor.execute(sql)
  File "F:\python\duobaodao\lib\site-packages\pymysql\cursors.py", line 170, in execute
    result = self._query(query)
  File "F:\python\duobaodao\lib\site-packages\pymysql\cursors.py", line 328, in _query
    conn.query(q)
  File "F:\python\duobaodao\lib\site-packages\pymysql\connections.py", line 517, in query
    self._affected_rows = self._read_query_result(unbuffered=unbuffered)
  File "F:\python\duobaodao\lib\site-packages\pymysql\connections.py", line 732, in _read_query_result
    result.read()
  File "F:\python\duobaodao\lib\site-packages\pymysql\connections.py", line 1075, in read
    first_packet = self.connection._read_packet()
  File "F:\python\duobaodao\lib\site-packages\pymysql\connections.py", line 684, in _read_packet
    packet.check_error()
  File "F:\python\duobaodao\lib\site-packages\pymysql\protocol.py", line 220, in check_error
    err.raise_mysql_exception(self._data)
  File "F:\python\duobaodao\lib\site-packages\pymysql\err.py", line 109, in raise_mysql_exception
    raise errorclass(errno, errval)
pymysql.err.IntegrityError: (1062, "Duplicate entry '202987266' for key 'goodsid'")

2020-02-19 20:51:43,944 - ERROR - Traceback (most recent call last):
  File "F:\python\duobaodao\Getgoods.py", line 240, in __setdata
    self.cursor.execute(sql)
  File "F:\python\duobaodao\lib\site-packages\pymysql\cursors.py", line 170, in execute
    result = self._query(query)
  File "F:\python\duobaodao\lib\site-packages\pymysql\cursors.py", line 328, in _query
    conn.query(q)
  File "F:\python\duobaodao\lib\site-packages\pymysql\connections.py", line 517, in query
    self._affected_rows = self._read_query_result(unbuffered=unbuffered)
  File "F:\python\duobaodao\lib\site-packages\pymysql\connections.py", line 732, in _read_query_result
    result.read()
  File "F:\python\duobaodao\lib\site-packages\pymysql\connections.py", line 1075, in read
    first_packet = self.connection._read_packet()
  File "F:\python\duobaodao\lib\site-packages\pymysql\connections.py", line 684, in _read_packet
    packet.check_error()
  File "F:\python\duobaodao\lib\site-packages\pymysql\protocol.py", line 220, in check_error
    err.raise_mysql_exception(self._data)
  File "F:\python\duobaodao\lib\site-packages\pymysql\err.py", line 109, in raise_mysql_exception
    raise errorclass(errno, errval)
pymysql.err.IntegrityError: (1062, "Duplicate entry '203070850' for key 'goodsid'")

2020-02-19 20:51:44,315 - ERROR - Traceback (most recent call last):
  File "F:\python\duobaodao\Getgoods.py", line 240, in __setdata
    self.cursor.execute(sql)
  File "F:\python\duobaodao\lib\site-packages\pymysql\cursors.py", line 170, in execute
    result = self._query(query)
  File "F:\python\duobaodao\lib\site-packages\pymysql\cursors.py", line 328, in _query
    conn.query(q)
  File "F:\python\duobaodao\lib\site-packages\pymysql\connections.py", line 517, in query
    self._affected_rows = self._read_query_result(unbuffered=unbuffered)
  File "F:\python\duobaodao\lib\site-packages\pymysql\connections.py", line 732, in _read_query_result
    result.read()
  File "F:\python\duobaodao\lib\site-packages\pymysql\connections.py", line 1075, in read
    first_packet = self.connection._read_packet()
  File "F:\python\duobaodao\lib\site-packages\pymysql\connections.py", line 684, in _read_packet
    packet.check_error()
  File "F:\python\duobaodao\lib\site-packages\pymysql\protocol.py", line 220, in check_error
    err.raise_mysql_exception(self._data)
  File "F:\python\duobaodao\lib\site-packages\pymysql\err.py", line 109, in raise_mysql_exception
    raise errorclass(errno, errval)
pymysql.err.IntegrityError: (1062, "Duplicate entry '203070851' for key 'goodsid'")

2020-02-19 21:23:00,173 - ERROR - Traceback (most recent call last):
  File "F:\python\duobaodao\Getgoods.py", line 242, in __setdata
    self.cursor.execute(sql)
  File "F:\python\duobaodao\lib\site-packages\pymysql\cursors.py", line 170, in execute
    result = self._query(query)
  File "F:\python\duobaodao\lib\site-packages\pymysql\cursors.py", line 328, in _query
    conn.query(q)
  File "F:\python\duobaodao\lib\site-packages\pymysql\connections.py", line 517, in query
    self._affected_rows = self._read_query_result(unbuffered=unbuffered)
  File "F:\python\duobaodao\lib\site-packages\pymysql\connections.py", line 732, in _read_query_result
    result.read()
  File "F:\python\duobaodao\lib\site-packages\pymysql\connections.py", line 1075, in read
    first_packet = self.connection._read_packet()
  File "F:\python\duobaodao\lib\site-packages\pymysql\connections.py", line 684, in _read_packet
    packet.check_error()
  File "F:\python\duobaodao\lib\site-packages\pymysql\protocol.py", line 220, in check_error
    err.raise_mysql_exception(self._data)
  File "F:\python\duobaodao\lib\site-packages\pymysql\err.py", line 109, in raise_mysql_exception
    raise errorclass(errno, errval)
pymysql.err.IntegrityError: (1062, "Duplicate entry '203059510' for key 'goodsid'")

2020-02-19 21:23:49,840 - ERROR - Traceback (most recent call last):
  File "F:\python\duobaodao\Getgoods.py", line 242, in __setdata
    self.cursor.execute(sql)
  File "F:\python\duobaodao\lib\site-packages\pymysql\cursors.py", line 170, in execute
    result = self._query(query)
  File "F:\python\duobaodao\lib\site-packages\pymysql\cursors.py", line 328, in _query
    conn.query(q)
  File "F:\python\duobaodao\lib\site-packages\pymysql\connections.py", line 517, in query
    self._affected_rows = self._read_query_result(unbuffered=unbuffered)
  File "F:\python\duobaodao\lib\site-packages\pymysql\connections.py", line 732, in _read_query_result
    result.read()
  File "F:\python\duobaodao\lib\site-packages\pymysql\connections.py", line 1075, in read
    first_packet = self.connection._read_packet()
  File "F:\python\duobaodao\lib\site-packages\pymysql\connections.py", line 684, in _read_packet
    packet.check_error()
  File "F:\python\duobaodao\lib\site-packages\pymysql\protocol.py", line 220, in check_error
    err.raise_mysql_exception(self._data)
  File "F:\python\duobaodao\lib\site-packages\pymysql\err.py", line 109, in raise_mysql_exception
    raise errorclass(errno, errval)
pymysql.err.IntegrityError: (1062, "Duplicate entry '203059510' for key 'goodsid'")

